I also just saw this in a non-s3 test run. This one is probably evidence of flakiness, since it has both succeeded and failed in git hash 1d933919ee964d8766ba028623d66ec20cd123ac:

{noformat}
 TestComputeStats.test_compute_stats[exec_option: {'disable_codegen': False, 'abort_on_error': 1, 'exec_single_node_rows_threshold': 0, 'batch_size': 0, 'num_nodes': 0} | table_format: text/none] 
[gw3] linux2 -- Python 2.6.6 /data/jenkins/workspace/impala-asf-master-core-repeated-runs/repos/Impala/bin/../infra/python/env/bin/python
metadata/test_compute_stats.py:45: in test_compute_stats
    self.run_test_case('QueryTest/compute-stats', vector, unique_database)
common/impala_test_suite.py:324: in run_test_case
    result = self.__execute_query(target_impalad_client, query, user=user)
common/impala_test_suite.py:532: in __execute_query
    return impalad_client.execute(query, user=user)
common/impala_connection.py:160: in execute
    return self.__beeswax_client.execute(sql_stmt, user=user)
beeswax/impala_beeswax.py:173: in execute
    handle = self.__execute_query(query_string.strip(), user=user)
beeswax/impala_beeswax.py:337: in __execute_query
    handle = self.execute_query_async(query_string, user=user)
beeswax/impala_beeswax.py:333: in execute_query_async
    return self.__do_rpc(lambda: self.imp_service.query(query,))
beeswax/impala_beeswax.py:458: in __do_rpc
    raise ImpalaBeeswaxException(self.__build_error_message(b), b)
E   ImpalaBeeswaxException: ImpalaBeeswaxException:
E    INNER EXCEPTION: <class 'beeswaxd.ttypes.BeeswaxException'>
E    MESSAGE: 
E   ImpalaRuntimeException: Error making 'createTable' RPC to Hive Metastore: 
E   CAUSED BY: AlreadyExistsException: Table avro_impala_alltypes_bad_coltype already exists
{noformat}

Hit this again in a build:


{code:java}
ERROR at setup of TestParquet.test_annotate_utf8_option[exec_option: {'disable_codegen': True, 'abort_on_error': 1, 'exec_single_node_rows_threshold': 0, 'batch_size': 0, 'num_nodes': 0} | table_format: parquet/none] 
16:42:53 [gw3] linux2 -- Python 2.6.6 /data/jenkins/workspace/impala-umbrella-build-and-test/repos/Impala/bin/../infra/python/env/bin/python
16:42:53 conftest.py:297: in unique_database
16:42:53     {'sync_ddl': sync_ddl})
16:42:53 common/impala_test_suite.py:475: in wrapper
16:42:53     return function(*args, **kwargs)
16:42:53 common/impala_test_suite.py:482: in execute_query_expect_success
16:42:53     result = cls.__execute_query(impalad_client, query, query_options)
16:42:53 common/impala_test_suite.py:567: in __execute_query
16:42:53     return impalad_client.execute(query, user=user)
16:42:53 common/impala_connection.py:160: in execute
16:42:53     return self.__beeswax_client.execute(sql_stmt, user=user)
16:42:53 beeswax/impala_beeswax.py:173: in execute
16:42:53     handle = self.__execute_query(query_string.strip(), user=user)
16:42:53 beeswax/impala_beeswax.py:337: in __execute_query
16:42:53     handle = self.execute_query_async(query_string, user=user)
16:42:53 beeswax/impala_beeswax.py:333: in execute_query_async
16:42:53     return self.__do_rpc(lambda: self.imp_service.query(query,))
16:42:53 beeswax/impala_beeswax.py:458: in __do_rpc
16:42:53     raise ImpalaBeeswaxException(self.__build_error_message(b), b)
16:42:53 E   ImpalaBeeswaxException: ImpalaBeeswaxException:
16:42:53 E    INNER EXCEPTION: <class 'beeswaxd.ttypes.BeeswaxException'>
16:42:53 E    MESSAGE: 
16:42:53 E   ImpalaRuntimeException: Error making 'createDatabase' RPC to Hive Metastore: 
16:42:53 E   CAUSED BY: AlreadyExistsException: Database test_annotate_utf8_option_fec254b1 already exists
16:42:53 ---------------------------- Captured stderr setup -----------------------------
{code}


[~sailesh], can you also add which build hit this?

Downgrading to "Critical", since these are not regressions from 2.8.0

Duplicates IMPALA-5177

