Observed this test failure in pre-commit test of an unrelated change. Looks like the expected number of concurrent queries reached 4 while it is expected to be 3 or less.
{code:java}
custom_cluster/test_executor_groups.py:293: in test_executor_concurrency
    assert max(num_running) == 3, \
E   AssertionError: Unexpected number of running queries: [3, 3, 3, 3, 3, 3, 3, 3, 3, 3, 3, 3, 3, 3, 3, 4, 3, 3, 3, 3, 3, 3, 3, 3, 3, 3, 3, 3, 3, 3]
E   assert 4 == 3
E    +  where 4 = max([3, 3, 3, 3, 3, 3, ...]) {code}
Â 